2024-12-28 19:25:00,996 - db_manager - INFO - Successfully connected to MongoDB
2024-12-28 19:25:00,998 - __main__ - INFO - Server listening on 0.0.0.0:5000
2024-12-28 19:25:10,207 - __main__ - INFO - Connection from ('192.168.1.200', 56910)
2024-12-28 19:25:10,216 - db_manager - INFO - Inserted document in users with ID: 67705096704494cd8ef8aed4
2024-12-28 19:25:10,216 - users - INFO - User created with ID: 67705096704494cd8ef8aed4
2024-12-28 19:30:25,508 - __main__ - INFO - Connection from ('192.168.1.200', 33146)
2024-12-28 19:30:25,518 - db_manager - INFO - Inserted document in notes with ID: 125bbcca-6134-4f27-b10a-6cc216855c64
2024-12-28 19:30:25,520 - notes - INFO - Note created with ID: 125bbcca-6134-4f27-b10a-6cc216855c64
2024-12-28 19:32:02,162 - __main__ - INFO - Connection from ('192.168.1.200', 34140)
2024-12-28 19:32:02,168 - db_manager - INFO - Inserted document in notes with ID: 9dcbab9e-4ae1-4d48-ac57-fb2c16d1ac9f
2024-12-28 19:32:02,169 - notes - INFO - Note created with ID: 9dcbab9e-4ae1-4d48-ac57-fb2c16d1ac9f
2024-12-28 19:34:53,320 - __main__ - INFO - Connection from ('192.168.1.200', 44858)
2024-12-28 19:34:53,324 - db_manager - INFO - Inserted document in notes with ID: 264f7753-0bcc-4da4-9ebe-025c0ba0a171
2024-12-28 19:34:53,325 - notes - INFO - Note created with ID: 264f7753-0bcc-4da4-9ebe-025c0ba0a171
2024-12-28 19:37:45,404 - __main__ - INFO - Connection from ('192.168.1.200', 50760)
2024-12-28 19:37:58,758 - __main__ - INFO - Connection from ('192.168.1.200', 40188)
2024-12-28 19:37:59,339 - __main__ - INFO - Connection from ('192.168.1.200', 40202)
2024-12-28 19:37:59,794 - __main__ - INFO - Connection from ('192.168.1.200', 40204)
2024-12-28 19:38:00,211 - __main__ - INFO - Connection from ('192.168.1.200', 40212)
2024-12-28 19:38:00,595 - __main__ - INFO - Connection from ('192.168.1.200', 40226)
2024-12-28 19:38:01,086 - __main__ - INFO - Connection from ('192.168.1.200', 40240)
2024-12-28 19:38:02,035 - __main__ - INFO - Connection from ('192.168.1.200', 40246)
2024-12-28 19:38:02,821 - __main__ - INFO - Connection from ('192.168.1.200', 40256)
2024-12-28 19:38:03,590 - __main__ - INFO - Connection from ('192.168.1.200', 40266)
2024-12-28 19:38:04,390 - __main__ - INFO - Connection from ('192.168.1.200', 40274)
2024-12-28 19:38:30,849 - __main__ - INFO - Connection from ('192.168.1.200', 54042)
2024-12-28 19:38:31,586 - __main__ - INFO - Connection from ('192.168.1.200', 54044)
2024-12-28 19:38:32,055 - __main__ - INFO - Connection from ('192.168.1.200', 54046)
2024-12-28 19:38:35,672 - __main__ - INFO - Connection from ('192.168.1.200', 54048)
2024-12-28 19:38:36,381 - __main__ - INFO - Connection from ('192.168.1.200', 54050)
2024-12-28 19:38:36,826 - __main__ - INFO - Connection from ('192.168.1.200', 54052)
2024-12-28 19:38:37,221 - __main__ - INFO - Connection from ('192.168.1.200', 54064)
2024-12-28 19:39:33,552 - __main__ - INFO - Connection from ('192.168.1.200', 33470)
2024-12-28 19:39:33,558 - db_manager - INFO - Inserted document in notes with ID: 9969319d-c53b-4460-baae-fa26e106faeb
2024-12-28 19:39:33,560 - notes - INFO - Note created with ID: 9969319d-c53b-4460-baae-fa26e106faeb
2024-12-28 22:08:25,843 - db_manager - ERROR - Error initializing MongoDB connection: 192.168.56.17:27017: [Errno 111] Connection refused (configured timeouts: socketTimeoutMS: 20000.0ms, connectTimeoutMS: 20000.0ms), Timeout: 30s, Topology Description: <TopologyDescription id: 677076bbe682b844d651c88d, topology_type: Unknown, servers: [<ServerDescription ('192.168.56.17', 27017) server_type: Unknown, rtt: None, error=AutoReconnect('192.168.56.17:27017: [Errno 111] Connection refused (configured timeouts: socketTimeoutMS: 20000.0ms, connectTimeoutMS: 20000.0ms)')>]>
Traceback (most recent call last):
  File "/home/vagrant/app/db_manager.py", line 77, in __init__
    server_info = self.client.server_info()
  File "/usr/local/lib/python3.8/dist-packages/pymongo/synchronous/mongo_client.py", line 2125, in server_info
    self.admin.command(
  File "/usr/local/lib/python3.8/dist-packages/pymongo/_csot.py", line 119, in csot_wrapper
    return func(self, *args, **kwargs)
  File "/usr/local/lib/python3.8/dist-packages/pymongo/synchronous/database.py", line 926, in command
    with self._client._conn_for_reads(read_preference, session, operation=command_name) as (
  File "/usr/local/lib/python3.8/dist-packages/pymongo/synchronous/mongo_client.py", line 1701, in _conn_for_reads
    server = self._select_server(read_preference, session, operation)
  File "/usr/local/lib/python3.8/dist-packages/pymongo/synchronous/mongo_client.py", line 1649, in _select_server
    server = topology.select_server(
  File "/usr/local/lib/python3.8/dist-packages/pymongo/synchronous/topology.py", line 398, in select_server
    server = self._select_server(
  File "/usr/local/lib/python3.8/dist-packages/pymongo/synchronous/topology.py", line 376, in _select_server
    servers = self.select_servers(
  File "/usr/local/lib/python3.8/dist-packages/pymongo/synchronous/topology.py", line 283, in select_servers
    server_descriptions = self._select_servers_loop(
  File "/usr/local/lib/python3.8/dist-packages/pymongo/synchronous/topology.py", line 333, in _select_servers_loop
    raise ServerSelectionTimeoutError(
pymongo.errors.ServerSelectionTimeoutError: 192.168.56.17:27017: [Errno 111] Connection refused (configured timeouts: socketTimeoutMS: 20000.0ms, connectTimeoutMS: 20000.0ms), Timeout: 30s, Topology Description: <TopologyDescription id: 677076bbe682b844d651c88d, topology_type: Unknown, servers: [<ServerDescription ('192.168.56.17', 27017) server_type: Unknown, rtt: None, error=AutoReconnect('192.168.56.17:27017: [Errno 111] Connection refused (configured timeouts: socketTimeoutMS: 20000.0ms, connectTimeoutMS: 20000.0ms)')>]>
2024-12-28 22:08:25,894 - root - ERROR - Error in database manager: 192.168.56.17:27017: [Errno 111] Connection refused (configured timeouts: socketTimeoutMS: 20000.0ms, connectTimeoutMS: 20000.0ms), Timeout: 30s, Topology Description: <TopologyDescription id: 677076bbe682b844d651c88d, topology_type: Unknown, servers: [<ServerDescription ('192.168.56.17', 27017) server_type: Unknown, rtt: None, error=AutoReconnect('192.168.56.17:27017: [Errno 111] Connection refused (configured timeouts: socketTimeoutMS: 20000.0ms, connectTimeoutMS: 20000.0ms)')>]>
2024-12-28 22:08:25,895 - root - ERROR - Error initializing the server: 192.168.56.17:27017: [Errno 111] Connection refused (configured timeouts: socketTimeoutMS: 20000.0ms, connectTimeoutMS: 20000.0ms), Timeout: 30s, Topology Description: <TopologyDescription id: 677076bbe682b844d651c88d, topology_type: Unknown, servers: [<ServerDescription ('192.168.56.17', 27017) server_type: Unknown, rtt: None, error=AutoReconnect('192.168.56.17:27017: [Errno 111] Connection refused (configured timeouts: socketTimeoutMS: 20000.0ms, connectTimeoutMS: 20000.0ms)')>]>
2024-12-28 22:08:52,198 - db_manager - INFO - Successfully connected to MongoDB
2024-12-28 22:08:52,199 - __main__ - INFO - Server listening on 0.0.0.0:5000
2024-12-28 22:10:23,166 - __main__ - INFO - Connection from ('192.168.1.200', 49666)
2024-12-28 22:10:23,172 - db_manager - INFO - Inserted document in users with ID: 6770774fed1f4f45b9cf817b
2024-12-28 22:10:23,173 - users - INFO - User created with ID: 6770774fed1f4f45b9cf817b
2024-12-28 22:10:46,660 - __main__ - INFO - Connection from ('192.168.1.200', 50786)
2024-12-28 22:10:46,664 - __main__ - ERROR - Error processing request: 'str' object has no attribute 'get'
2024-12-28 22:14:00,838 - __main__ - INFO - Connection from ('192.168.1.200', 37636)
2024-12-28 22:18:21,219 - __main__ - INFO - Connection from ('192.168.1.200', 39538)
2024-12-28 22:18:21,221 - users - ERROR - Error creating user: Username already exists
2024-12-28 22:18:21,222 - __main__ - ERROR - Error processing request: Username already exists
2024-12-28 22:18:31,118 - __main__ - INFO - Connection from ('192.168.1.200', 43892)
2024-12-28 22:18:31,121 - db_manager - INFO - Inserted document in users with ID: 67707937ed1f4f45b9cf817c
2024-12-28 22:18:31,121 - users - INFO - User created with ID: 67707937ed1f4f45b9cf817c
2024-12-28 22:20:57,792 - __main__ - INFO - Connection from ('192.168.1.200', 59594)
2024-12-28 22:22:17,242 - __main__ - INFO - Connection from ('192.168.1.200', 58858)
2024-12-28 22:56:05,621 - __main__ - INFO - Connection from ('192.168.1.200', 33666)
2024-12-28 22:58:08,860 - __main__ - INFO - Connection from ('192.168.1.200', 48726)
2024-12-28 23:03:21,737 - db_manager - INFO - MongoDB connection closed
2024-12-28 23:03:23,645 - db_manager - INFO - Successfully connected to MongoDB
2024-12-28 23:03:23,647 - __main__ - INFO - Server listening on 0.0.0.0:5000
2024-12-28 23:03:30,853 - __main__ - INFO - Connection from ('192.168.1.200', 49018)
2024-12-28 23:04:34,645 - __main__ - INFO - Connection from ('192.168.1.200', 54188)
2024-12-28 23:09:31,640 - __main__ - INFO - Connection from ('192.168.1.200', 43686)
2024-12-28 23:10:15,998 - __main__ - INFO - Connection from ('192.168.1.200', 50336)
2024-12-28 23:10:16,000 - users - ERROR - Error creating user: Username already exists
2024-12-28 23:10:16,000 - __main__ - ERROR - Error processing request: Username already exists
2024-12-28 23:10:25,203 - __main__ - INFO - Connection from ('192.168.1.200', 41486)
2024-12-28 23:10:25,207 - db_manager - INFO - Inserted document in users with ID: 677085613e6aef61bfcd397b
2024-12-28 23:10:25,207 - users - INFO - User created with ID: 677085613e6aef61bfcd397b
2024-12-28 23:10:53,051 - __main__ - INFO - Connection from ('192.168.1.200', 33346)
2024-12-28 23:12:07,591 - __main__ - INFO - Connection from ('192.168.1.200', 52096)
2024-12-28 23:12:12,184 - __main__ - INFO - Connection from ('192.168.1.200', 53634)
2024-12-28 23:12:26,260 - __main__ - INFO - Connection from ('192.168.1.200', 57802)
2024-12-28 23:12:53,337 - __main__ - INFO - Connection from ('192.168.1.200', 42150)
2024-12-28 23:14:22,561 - __main__ - INFO - Connection from ('192.168.1.200', 36860)
2024-12-28 23:14:23,593 - __main__ - INFO - Connection from ('192.168.1.200', 36862)
2024-12-28 23:15:53,380 - __main__ - INFO - Connection from ('192.168.1.200', 35148)
2024-12-28 23:15:53,383 - db_manager - INFO - Inserted document in users with ID: 677086a93e6aef61bfcd397c
2024-12-28 23:15:53,383 - users - INFO - User created with ID: 677086a93e6aef61bfcd397c
2024-12-28 23:15:56,055 - __main__ - INFO - Connection from ('192.168.1.200', 35160)
2024-12-28 23:17:01,135 - db_manager - INFO - MongoDB connection closed
2024-12-28 23:17:07,263 - db_manager - INFO - Successfully connected to MongoDB
2024-12-28 23:17:07,263 - __main__ - INFO - Server listening on 0.0.0.0:5000
2024-12-28 23:17:19,646 - __main__ - INFO - Connection from ('192.168.1.200', 45170)
2024-12-28 23:19:19,906 - __main__ - INFO - Connection from ('192.168.1.200', 40538)
2024-12-28 23:19:52,327 - __main__ - INFO - Connection from ('192.168.1.200', 37696)
2024-12-28 23:19:52,330 - db_manager - INFO - Inserted document in users with ID: 67708798bf45c0724efc4d79
2024-12-28 23:19:52,330 - users - INFO - User created with ID: 67708798bf45c0724efc4d79
2024-12-28 23:28:51,958 - __main__ - INFO - Connection from ('192.168.1.200', 33032)
2024-12-28 23:28:51,961 - db_manager - INFO - Inserted document in users with ID: 677089b3bf45c0724efc4d7a
2024-12-28 23:28:51,961 - users - INFO - User created with ID: 677089b3bf45c0724efc4d7a
2024-12-28 23:32:00,008 - __main__ - INFO - Connection from ('192.168.1.200', 39608)
2024-12-28 23:32:00,010 - db_manager - INFO - Inserted document in users with ID: 67708a70bf45c0724efc4d7b
2024-12-28 23:32:00,011 - users - INFO - User created with ID: 67708a70bf45c0724efc4d7b
2024-12-28 23:57:13,562 - __main__ - INFO - Connection from ('192.168.1.200', 43928)
2024-12-28 23:57:13,565 - __main__ - ERROR - Error processing request: 'dict' object has no attribute 'actions'
